Workbook

Sheet GUOO realFBS资费试算表
B2: GUOO realFBS物流资费试算表 OZON官方指定物流
C5: 商品实重(kg) | E5: 计费重量 | F5: =IF(OR(AND(D5>=2.001,D5<=30,D7>1501,D7<7000,SUM(H5:H7)<=310,H5<=150,H6<=80,H7<=80),AND(D5>=5.001,D5<=30,D7>7001,D7<250000,SUM(H5:H7)<=310,H5<=150,H6<=80,H7<=80)),MAX(H5*H6*H7/12000,D5),D5) -> 0 | G5: 长(cm) | I5: 此处填最长边
F6: 不用填，自动跳 | G6: 宽(cm)
C7: 商品成交价(卢布) | G7: 高(cm)
B9: 产品类型 | C9: 配送方式 | D9: 运输方式 | E9: 价格测算(元) | F9: 资费 | G9: 重量区间限制 | H9: 货值(卢布) | I9: 尺寸限制(厘米) | J9: 电池运输
B10: Extra Small (超级轻小件) | C10: GUOO Express Extra Small PUDO (特快超级轻小件到点) GUOO Express Extra Small Courier (特快超级轻小件到门) | D10: 空运 | E10: =IF(OR(D5>0.5,D7>1500,AND(SUM(H5:H7)>90),H5>60,H6>60,H7>60)," ",IF(OR($D$5=0,$D$7=0,$H$5=0,$H$6=0,$H$7=0)," ",F5*K10+L10)) | F10: =K10&"元/千克+"&L10&"元/票" -> 50.55元/千克+3.37元/票 | G10: 0.001-0.5KG | H10: 1-1500₽ | I10: ='GUOO FBP资费试算表'!I10&'GUOO FBP资费试算表'!J10 -> 渠道优势：适合重量0.001-0.5KG以内,货值1500卢布以内商品；例如：3C、小饰品等小件商品。 丢件：最高赔付1500卢布尺寸限制：三边之和不超90CM，不算材积，单边最长限制60CM，按实重，按克计费 | J10: 电池不允许 只接普货（不接带电、带磁、液体、粉末、刀具、仿牌等产品） | K10: 50.55 | L10: 3.37
C11: GUOO Standard Extra Small PUDO (标准超级轻小件到点) GUOO Standard Extra Small Courier (标准超级轻小件到门) | D11: 陆空联运 | E11: =IF(OR(D5>0.5,D7>1500,AND(SUM(H5:H7)>90),H5>60,H6>60,H7>60)," ",IF(OR($D$5=0,$D$7=0,$H$5=0,$H$6=0,$H$7=0)," ",F5*K11+L11)) | F11: =K11&"元/千克+"&L11&"元/票" -> 39.3元/千克+3.37元/票 | J11: 异形件:不收，只能走个人用品，不能走商业用品。限运带电类产品，小容量内置电池类（内置电池可以，配套电池禁运）具体看附件表格《限运和敏感寄送限制》 | K11: 39.3 | L11: 3.37
C12: GUOO Economy Extra Small PUDO (经济超级轻小件到点) GUOO Economy Extra Small Courier (经济超级轻小件到门) | D12: 陆运 | E12: =IF(OR(D5>0.5,D7>1500,AND(SUM(H5:H7)>90),H5>60,H6>60,H7>60)," ",IF(OR($D$5=0,$D$7=0,$H$5=0,$H$6=0,$H$7=0)," ",F5*K12+L12)) | F12: =K12&"元/千克+"&L12&"元/票" -> 28.1元/千克+3.37元/票 | K12: 28.1 | L12: 3.37
B13: Budget (低客单轻小件) | C13: GUOO Standard Budget PUDO (标准低客单价到点) GUOO Standard Budget Courier (标准低客单价到门) | D13: 陆空联运 | E13: =IF(OR(D5<0.5,D5>30,D7>1500,AND(SUM(H5:H7)>150),H5>60,H6>60,H7>60)," ",IF(OR($D$5=0,$D$7=0,$H$5=0,$H$6=0,$H$7=0)," ",F5*K13+L13)) | F13: =K13&"元/千克+"&L13&"元/票" -> 28.1元/千克+25.83元/票 | G13: 0.501-30KG | I13: ='GUOO FBP资费试算表'!J12 -> 尺寸限制：三边之和不超150CM，单边最大尺寸不超60CM，按实重，按克计费 | K13: 28.1 | L13: 25.83
C14: GUOO Economy Budget PUDO (经济低客单价到点) GUOO Economy Budget Courier (经济低客单价到门) | D14: 陆运 | E14: =IF(OR(D5<0.5,D5>30,D7>1500,AND(SUM(H5:H7)>150),H5>60,H6>60,H7>60)," ",IF(OR($D$5=0,$D$7=0,$H$5=0,$H$6=0,$H$7=0)," ",F5*K14+L14)) | F14: =K14&"元/千克+"&L14&"元/票" -> 19.1元/千克+25.83元/票 | K14: 19.1 | L14: 25.83
B15: Small (小件) | C15: GUOO Express Small PUDO (特快轻小件到点) GUOO Express Small Courier (特快轻小件到门) | D15: 空运 | E15: =IF(OR(D5>2,D7<1501,D7>7000,AND(SUM(H5:H7)>150),H5>60,H6>60,H7>60)," ",IF(OR($D$5=0,$D$7=0,$H$5=0,$H$6=0,$H$7=0)," ",F5*K15+L15)) | F15: =K15&"元/千克+"&L15&"元/票" -> 50.5元/千克+17.97元/票 | G15: 0.001-2KG | H15: 1501-7000₽ | I15: ='GUOO FBP资费试算表'!J12 -> 尺寸限制：三边之和不超150CM，单边最大尺寸不超60CM，按实重，按克计费 | J15: 电池不允许 只接普货（不接带电、带磁、液体、粉末、刀具、仿牌等产品） | K15: 50.5 | L15: 17.97
C16: GUOO Standard Small PUDO (标准轻小件到点) GUOO Standard Small Courier (标准轻小件到门) | D16: 陆空联运 | E16: =IF(OR(D5>2,D7<1501,D7>7000,AND(SUM(H5:H7)>150),H5>60,H6>60,H7>60)," ",IF(OR($D$5=0,$D$7=0,$H$5=0,$H$6=0,$H$7=0)," ",F5*K16+L16)) | F16: =K16&"元/千克+"&L16&"元/票" -> 39.3元/千克+17.97元/票 | J16: 异形件:不收，只能走个人用品，不能走商业用品。限运带电类产品，小容量内置电池类（内置电池可以，配套电池禁运）具体看附件表格《限运和敏感寄送限制》 | K16: 39.3 | L16: 17.97
C17: GUOO Economy Small PUDO (经济轻小件到点) GUOO Economy Small Courier (经济轻小件到门) | D17: 陆运 | E17: =IF(OR(D5>2,D7<1501,D7>7000,AND(SUM(H5:H7)>150),H5>60,H6>60,H7>60)," ",IF(OR($D$5=0,$D$7=0,$H$5=0,$H$6=0,$H$7=0)," ",F5*K17+L17)) | F17: =K17&"元/千克+"&L17&"元/票" -> 28.1元/千克+17.97元/票 | J17: 可以运输内部装有电池的物品 无需提供材料安全性数据表MSDS | K17: 28.1 | L17: 17.97
B18: Big (大件) | C18: GUOO Standard Big PUDO (标准大件到点) GUOO Standard Big Courier (标准大件到门) | D18: 陆空联运 | E18: =IF(OR(D5<2,D5>30,D7<1501,D7>7000,AND(SUM(H5:H7)>310),H5>150,H6>80,H7>80)," ",IF(OR($D$5=0,$D$7=0,$H$5=0,$H$6=0,$H$7=0)," ",F5*K18+L18)) | F18: =K18&"元/千克+"&L18&"元/票" -> 28.1元/千克+40.44元/票 | G18: 2.001-30KG 收抛 | I18: ='GUOO FBP资费试算表'!J16 -> 尺寸限制：三边之和不超310CM，单边最大尺寸不超150*80*80CM | J18: 不可运输纯电池 可以运输内部装有电池的物品 无需提供材料安全性数据表MSDS 最大功率为160瓦特一小时 | K18: 28.1 | L18: 40.44
C19: GUOO Economy Big PUDO (经济大件到点) GUOO Economy Big Courier (经济大件到门) | D19: 陆运 | E19: =IF(OR(D5<2,D5>30,D7<1501,D7>7000,AND(SUM(H5:H7)>310),H5>150,H6>80,H7>80)," ",IF(OR($D$5=0,$D$7=0,$H$5=0,$H$6=0,$H$7=0)," ",F5*K19+L19)) | F19: =K19&"元/千克+"&L19&"元/票" -> 19.1元/千克+40.44元/票 | J19: 可以运输内部装有电池的物品 无需提供材料安全性数据表MSDS | K19: 19.1 | L19: 40.44
B20: Premium Small (高客单轻小件) | C20: GUOO Express Premium Small PUDO (特快高客单价轻小件到点) GUOO Express Premium Small Courier (特快高客单价轻小件到门) | D20: 空运 | E20: =IF(OR(D5<0.001,D5>5,D7<7001,D7>250000,AND(SUM(H5:H7)>250),H5>150,H6>80,H7>80)," ",IF(OR($D$5=0,$D$7=0,$H$5=0,$H$6=0,$H$7=0)," ",F5*K20+L20)) | F20: =K20&"元/千克+"&L20&"元/票" -> 50.5元/千克+24.71元/票 | G20: 0.001-5KG | H20: 7001-250000₽ | I20: ='GUOO FBP资费试算表'!J18 -> 尺寸限制：三边之和不超250CM，单边最大尺寸不超150*80*80CM，按实重，按克计费 | J20: 电池不允许 只接普货（不接带电、带磁、液体、粉末、刀具、仿牌等产品） | K20: 50.5 | L20: 24.71
C21: GUOO Standard Premium Small PUDO (标准高客单价轻小件到点) GUOO Standard Premium Small Courier (标准高客单价轻小件到门) | D21: 陆空联运 | E21: =IF(OR(D5<0.001,D5>5,D7<7001,D7>250000,AND(SUM(H5:H7)>250),H5>150,H6>80,H7>80)," ",IF(OR($D$5=0,$D$7=0,$H$5=0,$H$6=0,$H$7=0)," ",F5*K21+L21)) | F21: =K21&"元/千克+"&L21&"元/票" -> 39.3元/千克+24.71元/票 | J21: 不可运输纯电池 可以运输内部装有电池的物品 无需提供材料安全性数据表MSDS 最大功率为160瓦特一小时 | K21: 39.3 | L21: 24.71
C22: GUOO Economy Premium Small PUDO (经济高客单价轻小件到点) GUOO Economy Premium Small Courier (经济高客单价轻小件到门) | D22: 陆运 | E22: =IF(OR(D5<0.001,D5>5,D7<7001,D7>250000,AND(SUM(H5:H7)>250),H5>150,H6>80,H7>80)," ",IF(OR($D$5=0,$D$7=0,$H$5=0,$H$6=0,$H$7=0)," ",F5*K22+L22)) | F22: =K22&"元/千克+"&L22&"元/票" -> 28.1元/千克+24.71元/票 | J22: 可以运输内部装有电池的物品 无需提供材料安全性数据表MSDS | K22: 28.1 | L22: 24.71
B23: Premium Big (高客单大件) | C23: GUOO Standard Premium Big PUDO (标准高客单价大件到点) GUOO Standard Premium Big Courier (标准高客单价大件到门) | D23: 陆空联运 | E23: =IF(OR(D5<5.001,D5>30,D7<7001,D7>250000,AND(SUM(H5:H7)>310),H5>150,H6>80,H7>80)," ",IF(OR($D$5=0,$D$7=0,$H$5=0,$H$6=0,$H$7=0)," ",F5*K23+L23)) | F23: =K23&"元/千克+"&L23&"元/票" -> 31.4元/千克+69.64元/票 | G23: 5.001-30KG 收抛 | I23: ='GUOO FBP资费试算表'!I20&'GUOO FBP资费试算表'!J20 -> 渠道优势：适合重量5.001KG-30KG以内,货值7001-250000卢布以内的商品。 丢件：最高赔付250000卢布尺寸限制：三边之和不超310CM，单边最大尺寸不超150*80*80CM | J23: 不可运输纯电池 可以运输内部装有电池的物品 无需提供材料安全性数据表MSDS 最大功率为160瓦特一小时 | K23: 31.4 | L23: 69.64
C24: GUOO Economy Premium Big PUDO (经济高客单价大件到点) GUOO Economy Premium Big Courier (经济高客单价大件到门) | D24: 陆运 | E24: =IF(OR(D5<5.001,D5>30,D7<7001,D7>250000,AND(SUM(H5:H7)>310),H5>150,H6>80,H7>80)," ",IF(OR($D$5=0,$D$7=0,$H$5=0,$H$6=0,$H$7=0)," ",F5*K24+L24)) | F24: =K24&"元/千克+"&L24&"元/票" -> 25.8元/千克+69.64元/票 | J24: 可以运输内部装有电池的物品 无需提供材料安全性数据表MSDS | K24: 25.8 | L24: 69.64
B25: 1. 本表仅用于物流运费测算，核算成本使用，结果数据仅供参考；
B26: 2. 请勿对表格数据改动，造成数据计算错误；
B27: 3. 重量默认单位为千克 KG，尺寸默认单位为厘米 CM，成交价是卢布；
B28: 4. 日常使用时，请按实际重量填写“商品重量/三边尺寸”和“商品货值”即可，表格自动生成对应物流报价；
B29: 5. 如显示“超出渠道限制”则为该订单重量或货值超出渠道限制。
B30: ※帮助页面链接
B31: 1. OZON帮助页面仓库创建教程：https://docs.ozon.ru/global/zh/fulfillment/rfbs/logistic-settings/warehouse/?country=CN
B32: 2. OZON帮助页面物流配送方式添加教程：https://docs.ozon.ru/global/zh/fulfillment/rfbs/logistic-settings/delivery-methods/?country=CN
B33: 3. OZON各类商品销售佣金标准：https://docs.ozon.ru/global/zh-hans/commissions/ozon-fees/commissions/?country=CN

Sheet GUOO FBP资费试算表
B2: GUOO FBP资费试算表 OZON官方指定物流
C5: 商品重量(kg) | F5: 计费重量 | G5: =IF(OR(AND(D5>=2.001,D5<=30,D7>1501,D7<7000,SUM(J5:J7)<=250,J5<=150,J6<=80,J7<=80),AND(D5>=5.001,D5<=30,D7>7001,D7<250000,SUM(J5:J7)<=310,J5<=150,J6<=80,J7<=80)),MAX(J5*J6*J7/12000,D5),D5) -> 0 | H5: 不用填，自动跳 | I5: 长(cm) | K5: 此处填最长边
I6: 宽(cm)
C7: 商品成交价(卢布) | I7: 高(cm)
B9: 产品类型 | C9: 配送方式 | D9: 运输方式 | E9: 价格测算(元) | F9: 资费(元) | G9: 重量区间限制 | H9: 货值(卢布) | I9: 渠道优势 | J9: 尺寸限制(厘米) | K9: 电池运输
B10: Extra Small (超级轻小件) | C10: GUOO ● FBP Economy ● Extra Small PUDO (GUOO经济超级轻小件到点) GUOO ● FBP Economy ● Extra Small Courier (GUOO经济超级轻小件到门) | D10: 陆运 | E10: =IF(OR(D5>0.5,D7>1500,AND(SUM(J5:J7)>90),J5>60,J6>60,J7>60)," ",IF(OR($D$5=0,$D$7=0,$J$5=0,$J$6=0,$J$7=0)," ",G5*L10+M10)) | F10: =L10&"元/千克+"&M10&"元/票" -> 28.1元/千克+3.37元/票 | G10: 0.001-0.5KG | H10: 1-1500₽ | I10: 渠道优势：适合重量0.001-0.5KG以内,货值1500卢布以内商品；例如：3C、小饰品等小件商品。 丢件：最高赔付1500卢布 | J10: 尺寸限制：三边之和不超90CM，不算材积，单边最长限制60CM，按实重，按克计费 | K10: 可以运输内部装有电池的物品 无需提供材料安全性数据表MSDS | L10: 28.1 | M10: 3.37
C11: GU0O ● FBP Standard ● Extra Small PUDO (GUOO FBP标准超级轻小件到点) GU0O ● FBP Standard ● Extra Small Courier (GUOO FBP标准超级轻小件到门) GUOO ● FBP Standard Extra Small ● Hh-pd （GUOO FBP Smart标准轻小件到点） | D11: 陆空 | E11: =IF(OR(D5>0.5,D7>1500,AND(SUM(J5:J7)>90),J5>60,J6>60,J7>60)," ",IF(OR($D$5=0,$D$7=0,$J$5=0,$J$6=0,$J$7=0)," ",G5*L11+M11)) | F11: =L11&"元/千克+"&M11&"元/票" -> 39.3元/千克+3.37元/票 | L11: 39.3 | M11: 3.37
B12: Budget (低客单轻小件) | C12: GUOO ● FBP Economy ● Budget PUDO (GUOO FBP经济低客单价到点) GUOO ● FBP Economy ● Budget Courier (GUOO FBP经济低客单价到门) GUOO ● FBP Economy Budget ● Hh-pd （GUOO FBP Smart经济低客单价到点） | D12: 陆运 | E12: =IF(OR(D5<0.501,D5>30,D7>1500,AND(SUM(J5:J7)>150),J5>60,J6>60,J7>60)," ",IF(OR($D$5=0,$D$7=0,$J$5=0,$J$6=0,$J$7=0)," ",G5*L12+M12)) | F12: =L12&"元/千克+"&M12&"元/票" -> 19.1元/千克+25.83元/票 | G12: 0.501-30KG | I12: 渠道优势：适合重量0.501-30KG以内,货值1500卢布以内的大件商品。 丢件：最高赔付1500卢布 | J12: 尺寸限制：三边之和不超150CM，单边最大尺寸不超60CM，按实重，按克计费 | L12: 19.1 | M12: 25.83
C13: GUOO ● FBP Standard ● Budget PUDO (GUOO FBP标准低客单价到点) GUOO ● FBP Standard ● Budget Courier (GUOO FBP标准低客单价到门) | D13: 陆空 | E13: =IF(OR(D5<0.501,D5>30,D7>1500,AND(SUM(J5:J7)>150),J5>60,J6>60,J7>60)," ",IF(OR($D$5=0,$D$7=0,$J$5=0,$J$6=0,$J$7=0)," ",G5*L13+M13)) | F13: =L13&"元/千克+"&M13&"元/票" -> 28.1元/千克+25.83元/票 | L13: 28.1 | M13: 25.83
B14: SMALL (轻小件) | C14: GUOO ● FBP Economy ● Small PUDO (GUOO FBP经济轻小件到点) GUOO ● FBP Economy ● Small Courier (GUOO FBP经济轻小件到门) | D14: 陆运 | E14: =IF(OR(D5>2,D7<1501,D7>7000,AND(SUM(J5:J7)>150),J5>60,J6>60,J7>60)," ",IF(OR($D$5=0,$D$7=0,$J$5=0,$J$6=0,$J$7=0)," ",G5*L14+M14)) | F14: =L14&"元/千克+"&M14&"元/票" -> 28.1元/千克+17.97元/票 | G14: 0.001-2KG | H14: 1501-7000₽ | I14: 渠道优势：适合重量0.001-2KG以内，货值1501-7000卢布以内的商品。 丢件：最高赔付7000卢布 | L14: 28.1 | M14: 17.97
C15: GUOO ● FBP Standard ● Small PUDO (GUOO FBP标准轻小件到点) GUOO ● FBP Standard ● Small Courier (GUOO FBP标准轻小件到门) GUOO ● FBP Standard Small ● Hh-pd （GUOO FBP Smart标准轻小件到点） GUOO ● FBP Standard Small ● Hh-cr （GUOO FBP Smart标准轻小件到门） | D15: 陆空 | E15: =IF(OR(D5>2,D7<1501,D7>7000,AND(SUM(J5:J7)>150),J5>60,J6>60,J7>60)," ",IF(OR($D$5=0,$D$7=0,$J$5=0,$J$6=0,$J$7=0)," ",G5*L15+M15)) | F15: =L15&"元/千克+"&M15&"元/票" -> 39.3元/千克+17.97元/票 | L15: 39.3 | M15: 17.97
B16: Big (大件) | C16: GUOO ● FBP Economy ● Big PUDO (GUOO FBP经济大件到点) GUOO ● FBP Economy ● Big Courier (GUOO FBP经济大件到门) GUOO ● FBP Economy Big ● Hh-pd （GUOO FBP Smart经济大件到点） GUOO ● FBP Economy Big ● Hh-cr （GUOO FBP Smart经济大件到门） | D16: 陆运 | E16: =IF(OR(D5<2.001,D5>30,D7<1501,D7>7000,AND(SUM(J5:J7)>310),J5>150,J6>80,J7>80)," ",IF(OR($D$5=0,$D$7=0,$J$5=0,$J$6=0,$J$7=0)," ",G5*L16+M16)) | F16: =L16&"元/千克+"&M16&"元/票" -> 19.1元/千克+40.44元/票 | G16: 2.001-30KG | I16: 渠道优势：适合重量2.001KG-30KG以内，货值1501-7000卢布以内的商品。 丢件：最高赔付7000卢布 | J16: 尺寸限制：三边之和不超310CM，单边最大尺寸不超150*80*80CM | L16: 19.1 | M16: 40.44
C17: GU00 ● FBP Standard ● Big PUDO (GUOO FBP标准大件到点) GU00 ● FBP Standard ● Big Courier (GUOO FBP标准大件到门) | D17: 陆空 | E17: =IF(OR(D5<2.001,D5>30,D7<1501,D7>7000,AND(SUM(J5:J7)>310),J5>150,J6>80,J7>80)," ",IF(OR($D$5=0,$D$7=0,$J$5=0,$J$6=0,$J$7=0)," ",G5*L17+M17)) | F17: =L17&"元/千克+"&M17&"元/票" -> 28.1元/千克+40.44元/票 | L17: 28.1 | M17: 40.44
B18: Premium Small (高客单轻小件) | C18: GUOO ● FBP Economy ● Premium Small PUDO (GUOO FBP经济高客单价轻小件到点) GUOO ● FBP Economy ● Premium Small Courier (GUOO FBP经济高客单价轻小件到门) | D18: 陆运 | E18: =IF(OR(D5<0.001,D5>5,D7<7001,D7>250000,AND(SUM(J5:J7)>250),J5>150,J6>80,J7>80)," ",IF(OR($D$5=0,$D$7=0,$J$5=0,$J$6=0,$J$7=0)," ",G5*L18+M18)) | F18: =L18&"元/千克+"&M18&"元/票" -> 28.1元/千克+24.71元/票 | G18: 0.001-5KG | H18: 7001-250000₽ | I18: 渠道优势：适合重量0.001KG-5KG以内，货值7001-250000卢布以内的商品。 丢件：最高赔付250000卢布 | J18: 尺寸限制：三边之和不超250CM，单边最大尺寸不超150*80*80CM，按实重，按克计费 | L18: 28.1 | M18: 24.71
C19: GUO0 ● FBP Standard ● Premium Small PUDO (GUOO FBP标准高客单价轻小件到点) GUO0 ● FBP Standard ● Premium Small Courier (GUOO FBP标准高客单价轻小件到门) GUOO ● FBP Standard Premium Small ● Hh-pd （GUOO FBP Smart标准高客单价轻小件到点） GUOO ● FBP Standard Premium Small ● Hh-cr （GUOO FBP Smart标准高客单价轻小件到门） | D19: 陆空 | E19: =IF(OR(D5<0.001,D5>5,D7<7001,D7>250000,AND(SUM(J5:J7)>250),J5>150,J6>80,J7>80)," ",IF(OR($D$5=0,$D$7=0,$J$5=0,$J$6=0,$J$7=0)," ",G5*L19+M19)) | F19: =L19&"元/千克+"&M19&"元/票" -> 39.3元/千克+24.71元/票 | L19: 39.3 | M19: 24.71
B20: Premium Big (高客单大件) | C20: GUOO ● FBP Economy ● Premium Big PUDO (GUOO FBP经济高客单价大件到点) GUOO ● FBP Economy ● Premium Big Courier (GUOO FBP经济高客单价大件到门) GUOO ● FBP Economy Premium Big ● Hh-pd （FBP Smart经济高客单价大件到点） GUOO ● FBP Economy Premium Big ● Hh-cr （FBP Smart经济高客单价大件到门） | D20: 陆运 | E20: =IF(OR(D5<5.001,D5>30,D7<7001,D7>250000,AND(SUM(J5:J7)>310),J5>150,J6>80,J7>80)," ",IF(OR($D$5=0,$D$7=0,$J$5=0,$J$6=0,$J$7=0)," ",G5*L20+M20)) | F20: =L20&"元/千克+"&M20&"元/票" -> 25.8元/千克+69.64元/票 | G20: 5.001-30KG | I20: 渠道优势：适合重量5.001KG-30KG以内,货值7001-250000卢布以内的商品。 丢件：最高赔付250000卢布 | J20: 尺寸限制：三边之和不超310CM，单边最大尺寸不超150*80*80CM | L20: 25.8 | M20: 69.64
C21: GU00 ● FBP Standard ● Premium Big PUDO (GUOO FBP标准高客单价大件到点) GU00 ● FBP Standard ● Premium Big Courier (GUOO FBP标准高客单价大件到门) | D21: 陆空 | E21: =IF(OR(D5<5.001,D5>30,D7<7001,D7>250000,AND(SUM(J5:J7)>310),J5>150,J6>80,J7>80)," ",IF(OR($D$5=0,$D$7=0,$J$5=0,$J$6=0,$J$7=0)," ",G5*L21+M21)) | F21: =L21&"元/千克+"&M21&"元/票" -> 31.4元/千克+69.64元/票 | L21: 31.4 | M21: 69.64
B22: GUOO FBP黑河边境仓 | D22: 黑河备货至莫斯科 时效6-10天 | F22: GUOO Heihe 1 Bonded(保税仓库)：黑龙江省黑河市爱辉区331国道黑河保税物流中心1号仓库 GUOO Heihe 2(非保税仓库)：黑龙江省黑河市爱辉区中央东大街百合路边民互市贸易交易点1-2号仓库 | K22: 仓库工作时间 周一至周日 08:00-19:00
B23: 1. 本表仅用于物流运费测算，核算成本使用，结果数据仅供参考；
B24: 2. 请勿对表格数据改动，造成数据计算错误；
B25: 3. 重量默认单位为千克 KG，尺寸默认单位为厘米 CM，成交价是卢布；
B26: 4. 日常使用时，请按实际重量填写“商品重量/三边尺寸”和“商品货值”即可，表格自动生成对应物流报价；
B27: 5. 如显示“超出渠道限制”则为该订单重量或货值超出渠道限制。
B28: 地址：黑龙江省黑河市爱辉区中央东大街百合路边民互市贸易交易点1-2号仓库 客服工作时间：周一至周六 09:00-18:00

Sheet GUOO YANDEX资费试算表
B2: GUOO Yandex物流资费测算表 Yandex官方指定物流
E3: 广东省东莞市洪梅镇望沙路115号易商洪梅物流园一层1号库1-4月台（GUOO转运中心） 客服工作时间：周一至周六 09:00-18:00
C5: 商品重量(kg) | G5: 长(cm) | I5: *填写为最长边
G6: 宽(cm)
C7: 商品成交价(卢布) | G7: 高(cm)
B9: 产品类型 | C9: 配送方式 | D9: 运输方式 | E9: 价格测算(卢布) | F9: 资费(RUB) | G9: 重量区间限制 (公斤) | H9: 货值(卢布) | I9: 尺寸限制(厘米) | J9: 电池运输
B10: Extra Small | C10: GTA-SUPER EXPRESS Extra Small | D10: 空运 | E10: =IF(OR($D$5>0.5,$D$7>1500,$H$5>60,$H$6>60,$H$7>60,SUM($H$5:$H$7)>90)," ",IF(OR($D$5=0,$D$7=0,$H$5=0,$H$6=0,$H$7=0)," ",$D$5*K10+L10)) | F10: =K10&"卢布/千克+"&L10&"卢布/票" -> 525卢布/千克+99卢布/票 | G10: 0.001-0.5KG | H10: 1-1500₽ | I10: 尺寸限制：三边之和不超90CM，不算材积，单边最长限制60CM，按实重，按克计费 渠道优势：适合重量0.001-0.5KG以内,货值1500卢布以内的大件商品。 丢件：最高赔付1500卢布 | J10: 电池不允许 只接普货（不接带电、带磁、液体、粉末、刀具、仿牌等产品） | K10: 525 | L10: 99
C11: GTA-EXPRESS Extra Small | D11: 陆空联运 | E11: =IF(OR($D$5>0.5,$D$7>1500,$H$5>60,$H$6>60,$H$7>60,SUM($H$5:$H$7)>90)," ",IF(OR($D$5=0,$D$7=0,$H$5=0,$H$6=0,$H$7=0)," ",$D$5*K11+L11)) | F11: =K11&"卢布/千克+"&L11&"卢布/票" -> 340卢布/千克+84卢布/票 | J11: 不可运输纯电池 可以运输内部装有电池的物品 无需提供材料安全性数据表MSDS 最大功率为160瓦特一小时 | K11: 340 | L11: 84
C12: GTA-SUPER ECONOMY Extra Small | D12: 陆运 | E12: =IF(OR($D$5>0.5,$D$7>1500,$H$5>60,$H$6>60,$H$7>60,SUM($H$5:$H$7)>90)," ",IF(OR($D$5=0,$D$7=0,$H$5=0,$H$6=0,$H$7=0)," ",$D$5*K12+L12)) | F12: =K12&"卢布/千克+"&L12&"卢布/票" -> 178卢布/千克+99卢布/票 | J12: 可以运输内部装有电池的物品 无需提供材料安全性数据表MSDS | K12: 178 | L12: 99
B13: 标准 | C13: GTA-SUPER EXPRESS | D13: 空运 | E13: =IF(OR(D5>30,D7<1501,D7>500000,H5>150,H6>80,H7>80)," ",IF(OR(D5=0,D7=0,H5=0,H6=0,H7=0)," ",ROUNDUP(D5,3)*1073+194)) | F13: =K13&"卢布/千克+"&L13&"卢布/票" -> 1058卢布/千克+196卢布/票 | G13: 0.001-30KG | H13: 1501-500000₽ | I13: 尺寸限制：单边最大尺寸不超150*80*80CM，按1克进制，实重计费 渠道优势：适合重量0.001-30000G以内,货值500000卢布以内商品。 丢件：最高赔付500000卢布 | J13: 电池不允许 只接普货（不接带电、带磁、液体、粉末、刀具、仿牌等产品） | K13: 1058 | L13: 196
C14: GTA-EXPRESS | D14: 陆空联运 | E14: =IF(OR(D5>30,D7<1501,D7>500000,H5>150,H6>80,H7>80)," ",IF(OR(D5=0,D7=0,H5=0,H6=0,H7=0)," ",ROUNDUP(D5,3)*698+180)) | F14: =K14&"卢布/千克+"&L14&"卢布/票" -> 680卢布/千克+180卢布/票 | J14: 不可运输纯电池 可以运输内部装有电池的物品 无需提供材料安全性数据表MSDS 最大功率为160瓦特一小时 | K14: 680 | L14: 180
C15: GTA-SUPER ECONOMY | D15: 陆运 | E15: =IF(OR(D5>30,D7<1501,D7>500000,H5>150,H6>80,H7>80)," ",IF(OR(D5=0,D7=0,H5=0,H6=0,H7=0)," ",ROUNDUP(D5,3)*426+194)) | F15: =K15&"卢布/千克+"&L15&"卢布/票" -> 415卢布/千克+186卢布/票 | J15: 可以运输内部装有电池的物品 无需提供材料安全性数据表MSDS | K15: 415 | L15: 186
B16: 1. 本表仅用于物流运费测算，核算成本使用，结果数据仅供参考；
B17: 2. 请勿对表格数据改动，造成数据计算错误；
B18: 3. 重量默认单位为千克 KG，尺寸默认单位为厘米 CM，成交价是卢布；
B19: 4. 日常使用时，请按实际重量填写“商品重量/三边尺寸”和“商品货值”即可，表格自动生成对应物流报价；
B20: 5. 如显示“超出渠道限制”则为该订单重量或货值超出渠道限制。

Sheet 哈萨克斯坦专线
B2: 哈萨克斯坦专线物流资费试算表 OZON官方指定物流
C5: 商品实重(kg) | E5: 计费重量 | F5: =D5 -> 0 | G5: 长(cm) | I5: 此处填最长边
F6: 不用填，自动跳 | G6: 宽(cm)
C7: 商品成交价(卢布) | G7: 高(cm)
B9: 产品类型 | C9: 配送方式 | D9: 运输方式 | E9: 价格测算(元) | F9: 资费 | G9: 重量区间限制 | H9: 货值(卢布) | I9: 尺寸限制(厘米) | J9: 电池运输
B10: Extra Small (超级轻小件) | C10: GUOO Kazakhstan Standard Extra Small | D10: 陆空 | E10: =IF(OR($D$5<0.001,$D$5>0.5,$D$7>1500,AND(SUM($H$5:$H$7)>90),$H$5>60,$H$6>60,$H$7>60)," ",IF(OR($D$5=0,$D$7=0,$H$5=0,$H$6=0,$H$7=0)," ",$F$5*K10+L10)) | F10: =K10&"元/千克+"&L10&"元/票" -> 36.4元/千克+3.12元/票 | G10: 0.001-0.5KG | H10: 1-1500₽ | I10: 尺寸限制：三边之和不超90CM，不算材积，单边最长限制60CM，按实重，按克计费 | J10: 异形件:不收，只能走个人用品，不能走商业用品，限运带电类产品，小容量内置电池类（内置电池可以，配套电池禁运）具体看附件表格《 限运和敏感寄送限制》 | K10: 36.4 | L10: 3.12
C11: GUOO Kazakhstan Economy Extra Small | D11: 陆运 | E11: =IF(OR($D$5<0.001,$D$5>0.5,$D$7>1500,AND(SUM($H$5:$H$7)>90),$H$5>60,$H$6>60,$H$7>60)," ",IF(OR($D$5=0,$D$7=0,$H$5=0,$H$6=0,$H$7=0)," ",$F$5*K11+L11)) | F11: =K11&"元/千克+"&L11&"元/票" -> 26元/千克+3.12元/票 | K11: 26 | L11: 3.12
B12: Budget (低客单轻小件) | C12: GUOO Kazakhstan Standard Budget | D12: 陆空 | E12: =IF(OR($D$5<0.501,$D$5>35,$D$7>1500,AND(SUM($H$5:$H$7)>150),$H$5>60,$H$6>60,$H$7>60)," ",IF(OR($D$5=0,$D$7=0,$H$5=0,$H$6=0,$H$7=0)," ",$F$5*K12+L12)) | F12: =K12&"元/千克+"&L12&"元/票" -> 26元/千克+23.92元/票 | G12: 0.501-35KG | I12: 尺寸限制：三边之和不超150CM，不算材积，单边最长限制60CM，按实重，按克计费 | K12: 26 | L12: 23.92
C13: GUOO Kazakhstan Economy Budget | D13: 陆运 | E13: =IF(OR($D$5<0.501,$D$5>35,$D$7>1500,AND(SUM($H$5:$H$7)>150),$H$5>60,$H$6>60,$H$7>60)," ",IF(OR($D$5=0,$D$7=0,$H$5=0,$H$6=0,$H$7=0)," ",$F$5*K13+L13)) | F13: =K13&"元/千克+"&L13&"元/票" -> 17.68元/千克+23.92元/票 | K13: 17.68 | L13: 23.92
B14: SMALL (轻小件) | C14: GUOO Kazakhstan Standard Small | D14: 陆空 | E14: =IF(OR($D$5<0.001,$D$5>2,$D$7>7000,$D$7<1501,AND(SUM($H$5:$H$7)>150),$H$5>60,$H$6>60,$H$7>60)," ",IF(OR($D$5=0,$D$7=0,$H$5=0,$H$6=0,$H$7=0)," ",$F$5*K14+L14)) | F14: =K14&"元/千克+"&L14&"元/票" -> 36.4元/千克+16.64元/票 | G14: 0.001-2KG | H14: 1501-7000₽ | K14: 36.4 | L14: 16.64
C15: GUOO Kazakhstan Economy Small | D15: 陆运 | E15: =IF(OR($D$5<0.001,$D$5>2,$D$7>7000,$D$7<1501,AND(SUM($H$5:$H$7)>150),$H$5>60,$H$6>60,$H$7>60)," ",IF(OR($D$5=0,$D$7=0,$H$5=0,$H$6=0,$H$7=0)," ",$F$5*K15+L15)) | F15: =K15&"元/千克+"&L15&"元/票" -> 26元/千克+16.64元/票 | K15: 26 | L15: 16.64
B16: Big (大件) | C16: GUOO Kazakhstan Standard Big | D16: 陆空 | E16: =IF(OR($D$5<2.001,$D$5>35,$D$7>7000,$D$7<1501,AND(SUM($H$5:$H$7)>250),$H$5>150,$H$6>150,$H$7>150)," ",IF(OR($D$5=0,$D$7=0,$H$5=0,$H$6=0,$H$7=0)," ",$F$5*K16+L16)) | F16: =K16&"元/千克+"&L16&"元/票" -> 26元/千克+37.44元/票 | G16: 2.001-35KG 【收抛】 | I16: 尺寸限制：三边之和不超310CM，不算材积，单边最长限制150CM，实重/体积重 取大值，按G计费（12000抛比） | K16: 26 | L16: 37.44
C17: GUOO Kazakhstan Economy Big | D17: 陆运 | E17: =IF(OR($D$5<2.001,$D$5>35,$D$7>7000,$D$7<1501,AND(SUM($H$5:$H$7)>250),$H$5>150,$H$6>150,$H$7>150)," ",IF(OR($D$5=0,$D$7=0,$H$5=0,$H$6=0,$H$7=0)," ",$F$5*K17+L17)) | F17: =K17&"元/千克+"&L17&"元/票" -> 17.68元/千克+37.44元/票 | K17: 17.68 | L17: 37.44
B18: Premium Small (高客单轻小件) | C18: GUOO Kazakhstan Standard Premium Small | D18: 陆空 | E18: =IF(OR($D$5<0.001,$D$5>5,$D$7>500000,$D$7<7001,AND(SUM($H$5:$H$7)>250),$H$5>150,$H$6>150,$H$7>150)," ",IF(OR($D$5=0,$D$7=0,$H$5=0,$H$6=0,$H$7=0)," ",$F$5*K18+L18)) | F18: =K18&"元/千克+"&L18&"元/票" -> 36.4元/千克+22.88元/票 | G18: 0.001-5KG | H18: 7001-500000₽ | I18: 尺寸限制：三边之和不超250CM，不算材积，单边最长限制150CM，按实重，按克计费 | K18: 36.4 | L18: 22.88
C19: GUOO Kazakhstan Economy Premium Small | D19: 陆运 | E19: =IF(OR($D$5<0.001,$D$5>5,$D$7>500000,$D$7<7001,AND(SUM($H$5:$H$7)>250),$H$5>150,$H$6>150,$H$7>150)," ",IF(OR($D$5=0,$D$7=0,$H$5=0,$H$6=0,$H$7=0)," ",$F$5*K19+L19)) | F19: =K19&"元/千克+"&L19&"元/票" -> 26元/千克+22.88元/票 | K19: 26 | L19: 22.88
B20: Premium Big (高客单大件) | C20: GUOO Kazakhstan Standard Premium Big | D20: 陆空 | E20: =IF(OR($D$5<5.001,$D$5>35,$D$7>500000,$D$7<7001,AND(SUM($H$5:$H$7)>310),$H$5>150,$H$6>150,$H$7>150)," ",IF(OR($D$5=0,$D$7=0,$H$5=0,$H$6=0,$H$7=0)," ",$F$5*K20+L20)) | F20: =K20&"元/千克+"&L20&"元/票" -> 29.12元/千克+64.48元/票 | G20: 5.001-35KG 【收抛】 | I20: 尺寸限制：三边之和不超310CM，不算材积，单边最长限制150CM，实重/体积重 取大值，按G计费（12000抛比） | K20: 29.12 | L20: 64.48
C21: GUOO Kazakhstan Economy Premium Big | D21: 陆运 | E21: =IF(OR($D$5<5.001,$D$5>35,$D$7>500000,$D$7<7001,AND(SUM($H$5:$H$7)>310),$H$5>150,$H$6>150,$H$7>150)," ",IF(OR($D$5=0,$D$7=0,$H$5=0,$H$6=0,$H$7=0)," ",$F$5*K21+L21)) | F21: =K21&"元/千克+"&L21&"元/票" -> 23.92元/千克+64.48元/票 | K21: 23.92 | L21: 64.48
B22: 1. 本表仅用于物流运费测算，核算成本使用，结果数据仅供参考；
B23: 2. 请勿对表格数据改动，造成数据计算错误；
B24: 3. 重量默认单位为千克 KG，尺寸默认单位为厘米 CM，成交价是卢布；
B25: Premium Small (高客单轻小件)
B26: 5. 如显示“超出渠道限制”则为该订单重量或货值超出渠道限制。
B27: ※帮助页面链接
B28: 1. OZON帮助页面仓库创建教程：https://docs.ozon.ru/global/zh/fulfillment/rfbs/logistic-settings/warehouse/?country=CN
B29: 2. OZON帮助页面物流配送方式添加教程：https://docs.ozon.ru/global/zh/fulfillment/rfbs/logistic-settings/delivery-methods/?country=CN
B30: 3. OZON各类商品销售佣金标准：https://docs.ozon.ru/global/zh-hans/commissions/ozon-fees/commissions/?country=CN

Sheet 白俄专线 
B2: 白俄专线物流资费试算表 OZON官方指定物流
C5: 商品实重(kg) | E5: 计费重量 | F5: =D5 -> 0 | G5: 长(cm) | I5: 此处填最长边
F6: 不用填，自动跳 | G6: 宽(cm)
C7: 商品成交价(卢布) | G7: 高(cm)
B9: 产品类型 | C9: 配送方式 | D9: 运输方式 | E9: 价格测算(元) | F9: 资费 | G9: 重量区间限制 | H9: 货值(卢布) | I9: 尺寸限制(厘米) | J9: 电池运输
B10: Extra Small (超级轻小件) | C10: GUOO Belarus Standard Extra Small | D10: 陆空 | E10: =IF(OR($D$5<0.001,$D$5>0.5,$D$7>1500,AND(SUM($H$5:$H$7)>90),$H$5>60,$H$6>60,$H$7>60)," ",IF(OR($D$5=0,$D$7=0,$H$5=0,$H$6=0,$H$7=0)," ",$F$5*K10+L10)) | F10: =K10&"元/千克+"&L10&"元/票" -> 36.4元/千克+3.12元/票 | G10: 0.001-0.5KG | H10: 1-1500₽ | I10: 尺寸限制：三边之和不超90CM，不算材积，单边最长限制60CM，按实重，按克计费 | J10: 异形件:不收，只能走个人用品，不能走商业用品，限运带电类产品，小容量内置电池类（内置电池可以，配套电池禁运）具体看附件表格《 限运和敏感寄送限制》 | K10: 36.4 | L10: 3.12
C11: GUOO Belarus Economy Extra Small | D11: 陆运 | E11: =IF(OR($D$5<0.001,$D$5>0.5,$D$7>1500,AND(SUM($H$5:$H$7)>90),$H$5>60,$H$6>60,$H$7>60)," ",IF(OR($D$5=0,$D$7=0,$H$5=0,$H$6=0,$H$7=0)," ",$F$5*K11+L11)) | F11: =K11&"元/千克+"&L11&"元/票" -> 26元/千克+3.12元/票 | K11: 26 | L11: 3.12
B12: Budget (低客单轻小件) | C12: GUOO Belarus Standard Budget | D12: 陆空 | E12: =IF(OR($D$5<0.501,$D$5>35,$D$7>1500,AND(SUM($H$5:$H$7)>150),$H$5>60,$H$6>60,$H$7>60)," ",IF(OR($D$5=0,$D$7=0,$H$5=0,$H$6=0,$H$7=0)," ",$F$5*K12+L12)) | F12: =K12&"元/千克+"&L12&"元/票" -> 26元/千克+23.92元/票 | G12: 0.501-35KG | I12: 尺寸限制：三边之和不超150CM，不算材积，单边最长限制60CM，按实重，按克计费 | K12: 26 | L12: 23.92
C13: GUOO Belarus Economy Budget | D13: 陆运 | E13: =IF(OR($D$5<0.501,$D$5>35,$D$7>1500,AND(SUM($H$5:$H$7)>150),$H$5>60,$H$6>60,$H$7>60)," ",IF(OR($D$5=0,$D$7=0,$H$5=0,$H$6=0,$H$7=0)," ",$F$5*K13+L13)) | F13: =K13&"元/千克+"&L13&"元/票" -> 17.68元/千克+23.92元/票 | K13: 17.68 | L13: 23.92
B14: SMALL (轻小件) | C14: GUOO Belarus Standard Small | D14: 陆空 | E14: =IF(OR($D$5<0.001,$D$5>2,$D$7>7000,$D$7<1501,AND(SUM($H$5:$H$7)>150),$H$5>60,$H$6>60,$H$7>60)," ",IF(OR($D$5=0,$D$7=0,$H$5=0,$H$6=0,$H$7=0)," ",$F$5*K14+L14)) | F14: =K14&"元/千克+"&L14&"元/票" -> 36.4元/千克+16.64元/票 | G14: 0.001-2KG | H14: 1501-7000₽ | K14: 36.4 | L14: 16.64
C15: GUOO Belarus Economy Small | D15: 陆运 | E15: =IF(OR($D$5<0.001,$D$5>2,$D$7>7000,$D$7<1501,AND(SUM($H$5:$H$7)>150),$H$5>60,$H$6>60,$H$7>60)," ",IF(OR($D$5=0,$D$7=0,$H$5=0,$H$6=0,$H$7=0)," ",$F$5*K15+L15)) | F15: =K15&"元/千克+"&L15&"元/票" -> 26元/千克+16.64元/票 | K15: 26 | L15: 16.64
B16: Big (大件) | C16: GUOO Belarus Standard Big | D16: 陆空 | E16: =IF(OR($D$5<2.001,$D$5>35,$D$7>7000,$D$7<1501,AND(SUM($H$5:$H$7)>250),$H$5>150,$H$6>150,$H$7>150)," ",IF(OR($D$5=0,$D$7=0,$H$5=0,$H$6=0,$H$7=0)," ",$F$5*K16+L16)) | F16: =K16&"元/千克+"&L16&"元/票" -> 26元/千克+37.44元/票 | G16: 2.001-35KG 【收抛】 | I16: 尺寸限制:三边之和不超310CM，不算材 积，单边最长限制150CM，实重/体积重 取大值，按G计费(12000抛比) | K16: 26 | L16: 37.44
C17: GUOO Belarus Economy Big | D17: 陆运 | E17: =IF(OR($D$5<2.001,$D$5>35,$D$7>7000,$D$7<1501,AND(SUM($H$5:$H$7)>250),$H$5>150,$H$6>150,$H$7>150)," ",IF(OR($D$5=0,$D$7=0,$H$5=0,$H$6=0,$H$7=0)," ",$F$5*K17+L17)) | F17: =K17&"元/千克+"&L17&"元/票" -> 17.68元/千克+37.44元/票 | K17: 17.68 | L17: 37.44
B18: Premium Small (高客单轻小件) | C18: GUOO Belarus Standard Premium Small | D18: 陆空 | E18: =IF(OR($D$5<0.001,$D$5>5,$D$7>500000,$D$7<7001,AND(SUM($H$5:$H$7)>250),$H$5>150,$H$6>150,$H$7>150)," ",IF(OR($D$5=0,$D$7=0,$H$5=0,$H$6=0,$H$7=0)," ",$F$5*K18+L18)) | F18: =K18&"元/千克+"&L18&"元/票" -> 36.4元/千克+22.88元/票 | G18: 0.001-5KG | H18: 7001-500000₽ | I18: 尺寸限制：三边之和不超250CM，不算材积，单边最长限制150CM，按实重，按克计费 | K18: 36.4 | L18: 22.88
C19: GUOO Belarus Economy Premium Small | D19: 陆运 | E19: =IF(OR($D$5<0.001,$D$5>5,$D$7>500000,$D$7<7001,AND(SUM($H$5:$H$7)>250),$H$5>150,$H$6>150,$H$7>150)," ",IF(OR($D$5=0,$D$7=0,$H$5=0,$H$6=0,$H$7=0)," ",$F$5*K19+L19)) | F19: =K19&"元/千克+"&L19&"元/票" -> 26元/千克+22.88元/票 | K19: 26 | L19: 22.88
B20: Premium Big (高客单大件) | C20: GUOO Belarus Standard Premium Big | D20: 陆空 | E20: =IF(OR($D$5<5.001,$D$5>35,$D$7>500000,$D$7<7001,AND(SUM($H$5:$H$7)>310),$H$5>150,$H$6>150,$H$7>150)," ",IF(OR($D$5=0,$D$7=0,$H$5=0,$H$6=0,$H$7=0)," ",$F$5*K20+L20)) | F20: =K20&"元/千克+"&L20&"元/票" -> 29.12元/千克+64.48元/票 | G20: 5.001-35KG 【收抛】 | I20: 尺寸限制:三边之和不超310CM，不算材 积，单边最长限制150CM，实重/体积重 取大值，按G计费(12000抛比) | K20: 29.12 | L20: 64.48
C21: GUOO Belarus Economy Premium Big | D21: 陆运 | E21: =IF(OR($D$5<5.001,$D$5>35,$D$7>500000,$D$7<7001,AND(SUM($H$5:$H$7)>310),$H$5>150,$H$6>150,$H$7>150)," ",IF(OR($D$5=0,$D$7=0,$H$5=0,$H$6=0,$H$7=0)," ",$F$5*K21+L21)) | F21: =K21&"元/千克+"&L21&"元/票" -> 23.92元/千克+64.48元/票 | K21: 23.92 | L21: 64.48
B22: 1. 本表仅用于物流运费测算，核算成本使用，结果数据仅供参考；
B23: 2. 请勿对表格数据改动，造成数据计算错误；
B24: 3. 重量默认单位为千克 KG，尺寸默认单位为厘米 CM，成交价是卢布；
B25: Premium Small (高客单轻小件)
B26: 5. 如显示“超出渠道限制”则为该订单重量或货值超出渠道限制。
B27: ※帮助页面链接
B28: 1. OZON帮助页面仓库创建教程：https://docs.ozon.ru/global/zh/fulfillment/rfbs/logistic-settings/warehouse/?country=CN
B29: 2. OZON帮助页面物流配送方式添加教程：https://docs.ozon.ru/global/zh/fulfillment/rfbs/logistic-settings/delivery-methods/?country=CN
B30: 3. OZON各类商品销售佣金标准：https://docs.ozon.ru/global/zh-hans/commissions/ozon-fees/commissions/?country=CN

Sheet 吉尔吉斯斯坦
B2: 吉尔吉斯斯坦专线物流资费试算表 OZON官方指定物流
C5: 商品实重(kg) | E5: 计费重量 | F5: =D5 -> 0 | G5: 长(cm) | I5: 此处填最长边
F6: 不用填，自动跳 | G6: 宽(cm)
C7: 商品成交价(卢布) | G7: 高(cm)
B9: 产品类型 | C9: 配送方式 | D9: 运输方式 | E9: 价格测算(元) | F9: 资费 | G9: 重量区间限制 | H9: 货值(卢布) | I9: 尺寸限制(厘米) | J9: 电池运输
B10: Extra Small (超级轻小件) | C10: GUOO Kyrgyzstan Economy Extra Small | D10: 陆运 | E10: =IF(OR($D$5<0.001,$D$5>0.5,$D$7>1500,AND(SUM($H$5:$H$7)>90),$H$5>60,$H$6>60,$H$7>60)," ",IF(OR($D$5=0,$D$7=0,$H$5=0,$H$6=0,$H$7=0)," ",$F$5*K10+L10)) | F10: =K10&"元/千克+"&L10&"元/票" -> 26元/千克+3.12元/票 | G10: 0.001-0.5KG | H10: 1-1500 | I10: 尺寸限制：三边之和不超90CM，不算材积，单边最长限制60CM，按实重，按克计费 | J10: 1.只能走个人用品，不能走商业用品. 2异形件：不收. 3.限运带电类产品，小容量内置电池类（内置电池可以，配套电池禁运）具体看附件表格《 限运和敏感寄送限制》 | K10: 26 | L10: 3.12
B11: Budget (低客单轻小件) | C11: GUOO Kyrgyzstan Economy Budget | D11: 陆运 | E11: =IF(OR($D$5<0.501,$D$5>30,$D$7>1500,AND(SUM($H$5:$H$7)>150),$H$5>60,$H$6>60,$H$7>60)," ",IF(OR($D$5=0,$D$7=0,$H$5=0,$H$6=0,$H$7=0)," ",$F$5*K11+L11)) | F11: =K11&"元/千克+"&L11&"元/票" -> 17.68元/千克+23.92元/票 | G11: 0.501-30KG | I11: 尺寸限制：三边之和不超150CM，不算材积，单边最长限制60CM，按实重，按克计费 | K11: 17.68 | L11: 23.92
B12: SMALL (轻小件) | C12: GUOO Kyrgyzstan Economy Small | D12: 陆运 | E12: =IF(OR($D$5<0.001,$D$5>2,$D$7>7000,$D$7<1501,AND(SUM($H$5:$H$7)>150),$H$5>60,$H$6>60,$H$7>60)," ",IF(OR($D$5=0,$D$7=0,$H$5=0,$H$6=0,$H$7=0)," ",$F$5*K12+L12)) | F12: =K12&"元/千克+"&L12&"元/票" -> 26元/千克+16.64元/票 | G12: 0.001-2KG | H12: 1501-7000 | K12: 26 | L12: 16.64
B13: Big (大件) | C13: GUOO Kyrgyzstan Economy Big | D13: 陆运 | E13: =IF(OR($D$5<2.001,$D$5>30,$D$7>7000,$D$7<1501,AND(SUM($H$5:$H$7)>310),$H$5>150,$H$6>150,$H$7>150)," ",IF(OR($D$5=0,$D$7=0,$H$5=0,$H$6=0,$H$7=0)," ",$F$5*K13+L13)) | F13: =K13&"元/千克+"&L13&"元/票" -> 17.68元/千克+37.44元/票 | G13: 2.001-30KG | I13: 尺寸限制：三边之和不超310CM，不算材积，单边最长限制150CM，按实重，按克计费 | K13: 17.68 | L13: 37.44
B14: Premium Small (高客单轻小件) | C14: GUOO Kyrgyzstan Economy Premium Big | D14: 陆运 | E14: =IF(OR($D$5<0.001,$D$5>5,$D$7>500000,$D$7<7001,AND(SUM($H$5:$H$7)>250),$H$5>150,$H$6>150,$H$7>150)," ",IF(OR($D$5=0,$D$7=0,$H$5=0,$H$6=0,$H$7=0)," ",$F$5*K14+L14)) | F14: =K14&"元/千克+"&L14&"元/票" -> 26元/千克+22.88元/票 | G14: 0.001-5KG | H14: 7000-18000 | I14: 尺寸限制：三边之和不超250CM，不算材积，单边最长限制150CM，按实重，按克计费 | K14: 26 | L14: 22.88
B15: Premium Big (高客单大件) | C15: GUOO Kyrgyzstan Economy Premium Small | D15: 陆运 | E15: =IF(OR($D$5<5.001,$D$5>35,$D$7>500000,$D$7<7001,AND(SUM($H$5:$H$7)>310),$H$5>150,$H$6>150,$H$7>150)," ",IF(OR($D$5=0,$D$7=0,$H$5=0,$H$6=0,$H$7=0)," ",$F$5*K15+L15)) | F15: =K15&"元/千克+"&L15&"元/票" -> 23.92元/千克+64.48元/票 | G15: 5.001-30KG | I15: 尺寸限制：三边之和不超310CM，不算材积，单边最长限制150CM，按实重，按克计费 | K15: 23.92 | L15: 64.48
B16: 1. 本表仅用于物流运费测算，核算成本使用，结果数据仅供参考；
B17: 2. 请勿对表格数据改动，造成数据计算错误；
B18: 3. 重量默认单位为千克 KG，尺寸默认单位为厘米 CM，成交价是卢布；
B19: Premium Small (高客单轻小件)
B20: 5. 如显示“超出渠道限制”则为该订单重量或货值超出渠道限制。
B21: ※帮助页面链接
B22: 1. OZON帮助页面仓库创建教程：https://docs.ozon.ru/global/zh/fulfillment/rfbs/logistic-settings/warehouse/?country=CN
B23: 2. OZON帮助页面物流配送方式添加教程：https://docs.ozon.ru/global/zh/fulfillment/rfbs/logistic-settings/delivery-methods/?country=CN
B24: 3. OZON各类商品销售佣金标准：https://docs.ozon.ru/global/zh-hans/commissions/ozon-fees/commissions/?country=CN

Sheet 乌兹别克斯坦
B2: 乌兹别克斯坦专线物流资费试算表 OZON官方指定物流
C5: 商品实重(kg) | E5: 计费重量 | F5: =D5 -> 0 | G5: 长(cm) | I5: 此处填最长边
F6: 不用填，自动跳 | G6: 宽(cm)
C7: 商品成交价(卢布) | G7: 高(cm)
B9: 产品类型 | C9: 配送方式 | D9: 运输方式 | E9: 价格测算(元) | F9: 资费 | G9: 重量区间限制 | H9: 货值(卢布) | I9: 尺寸限制(厘米) | J9: 电池运输
B10: Extra Small (超级轻小件) | C10: GUOO Uzbekistan Economy Extra Small | D10: 陆运 | E10: =IF(OR($D$5<0.001,$D$5>0.5,$D$7>1500,AND(SUM($H$5:$H$7)>90),$H$5>60,$H$6>60,$H$7>60)," ",IF(OR($D$5=0,$D$7=0,$H$5=0,$H$6=0,$H$7=0)," ",$F$5*K10+L10)) | F10: =K10&"元/千克+"&L10&"元/票" -> 26元/千克+3.12元/票 | G10: 0.001-0.5KG | H10: 1-1500 | I10: 尺寸限制：三边之和不超90CM，不算材积，单边最长限制60CM，按实重，按克计费 | J10: 1.只能走个人用品，不能走商业用品. 2异形件：不收. 3.限运带电类产品，小容量内置电池类（内置电池可以，配套电池禁运）具体看附件表格《 限运和敏感寄送限制》 | K10: 26 | L10: 3.12
B11: Budget (低客单轻小件) | C11: GUOO Uzbekistan Economy Budget | D11: 陆运 | E11: =IF(OR($D$5<0.501,$D$5>30,$D$7>1500,AND(SUM($H$5:$H$7)>150),$H$5>60,$H$6>60,$H$7>60)," ",IF(OR($D$5=0,$D$7=0,$H$5=0,$H$6=0,$H$7=0)," ",$F$5*K11+L11)) | F11: =K11&"元/千克+"&L11&"元/票" -> 17.68元/千克+23.92元/票 | G11: 0.501-30KG | I11: 尺寸限制：三边之和不超150CM，不算材积，单边最长限制60CM，按实重，按克计费 | K11: 17.68 | L11: 23.92
B12: SMALL (轻小件) | C12: GUOO Uzbekistan Economy Small | D12: 陆运 | E12: =IF(OR($D$5<0.001,$D$5>2,$D$7>7000,$D$7<1501,AND(SUM($H$5:$H$7)>150),$H$5>60,$H$6>60,$H$7>60)," ",IF(OR($D$5=0,$D$7=0,$H$5=0,$H$6=0,$H$7=0)," ",$F$5*K12+L12)) | F12: =K12&"元/千克+"&L12&"元/票" -> 26元/千克+16.64元/票 | G12: 0.001-2KG | H12: 1501-7000 | K12: 26 | L12: 16.64
B13: Big (大件) | C13: GUOO Uzbekistan Economy Big | D13: 陆运 | E13: =IF(OR($D$5<2.001,$D$5>30,$D$7>7000,$D$7<1501,AND(SUM($H$5:$H$7)>310),$H$5>150,$H$6>150,$H$7>150)," ",IF(OR($D$5=0,$D$7=0,$H$5=0,$H$6=0,$H$7=0)," ",$F$5*K13+L13)) | F13: =K13&"元/千克+"&L13&"元/票" -> 17.68元/千克+37.44元/票 | G13: 2.001-30KG | I13: 尺寸限制：三边之和不超310CM，不算材积，单边最长限制150CM，按实重，按克计费 | K13: 17.68 | L13: 37.44
B14: Premium Small (高客单轻小件) | C14: GUOO Uzbekistan Economy Premium Small | D14: 陆运 | E14: =IF(OR($D$5<0.001,$D$5>5,$D$7>500000,$D$7<7001,AND(SUM($H$5:$H$7)>250),$H$5>150,$H$6>150,$H$7>150)," ",IF(OR($D$5=0,$D$7=0,$H$5=0,$H$6=0,$H$7=0)," ",$F$5*K14+L14)) | F14: =K14&"元/千克+"&L14&"元/票" -> 26元/千克+22.88元/票 | G14: 0.001-5KG | H14: 7000-18000 | I14: 尺寸限制：三边之和不超250CM，不算材积，单边最长限制150CM，按实重，按克计费 | K14: 26 | L14: 22.88
B15: Premium Big (高客单大件) | C15: GUOO Uzbekistan Economy Premium Big | D15: 陆运 | E15: =IF(OR($D$5<5.001,$D$5>30,$D$7>500000,$D$7<7001,AND(SUM($H$5:$H$7)>310),$H$5>150,$H$6>150,$H$7>150)," ",IF(OR($D$5=0,$D$7=0,$H$5=0,$H$6=0,$H$7=0)," ",$F$5*K15+L15)) | F15: =K15&"元/千克+"&L15&"元/票" -> 23.92元/千克+64.48元/票 | G15: 5.001-30KG | I15: 尺寸限制：三边之和不超310CM，不算材积，单边最长限制150CM，按实重，按克计费 | K15: 23.92 | L15: 64.48
B16: 1. 本表仅用于物流运费测算，核算成本使用，结果数据仅供参考；
B17: 2. 请勿对表格数据改动，造成数据计算错误；
B18: 3. 重量默认单位为千克 KG，尺寸默认单位为厘米 CM，成交价是卢布；
B19: Premium Small (高客单轻小件)
B20: 5. 如显示“超出渠道限制”则为该订单重量或货值超出渠道限制。
B21: ※帮助页面链接
B22: 1. OZON帮助页面仓库创建教程：https://docs.ozon.ru/global/zh/fulfillment/rfbs/logistic-settings/warehouse/?country=CN
B23: 2. OZON帮助页面物流配送方式添加教程：https://docs.ozon.ru/global/zh/fulfillment/rfbs/logistic-settings/delivery-methods/?country=CN
B24: 3. OZON各类商品销售佣金标准：https://docs.ozon.ru/global/zh-hans/commissions/ozon-fees/commissions/?country=CN

Sheet GUOO仓库地址&一件代发服务
B2: GUOO仓库地址&一件代发服务
B3: 揽收仓 | C3: 服务 | D3: 使用系统 | E3: 仓库代码 | F3: 仓库地址 | G3: 工作时间
B4: GUOO总部 深圳仓 | C4: 自贴单 | D4: 自贴单 | E4: / | F4: 广东省深圳市龙岗区平湖街道新厦大道180号3号仓(自贴单) 联系人：廖女士；手机号码：075589977386 联系人：谭生；手机号码：13202251622 | G4: 周一至周六 上午9:00至下午00:00
B5: 华东操作中心 黑河边境仓 | C5: 一件代发 | D5: WMS | E5: WMS使用手机号码注册 | F5: 黑龙江省黑河市爱辉区幸福乡黑河自贸区二公河工业园区孵化基地一期1号场房1-2号门(客户代码) 联系人：杨东升，手机号码：19532223242 | G5: 周一至周日 上午9:00至下午18:00
D6: 跨境巴士 | E6: A01华东操作中心 | F6: 黑龙江省黑河市爱辉区黑河自贸园区二公河工业园区孵化基地一期1号场房7号门(备注跨境巴士注册ID) 收件人：闫雪，手机号码：18032250092
B7: 华南操作中心 东莞仓 | C7: 一件代发 | D7: WMS | E7: WMS使用手机号码注册 | F7: 广东省东莞市洪梅镇望沙路115号易商物流园1楼2-2月台(客户代码) 收件人：陈勇，手机号码：13480991809 | G7: 周一至周日 上午8:00至下午20:00
D8: 跨境巴士 | E8: A02华南操作中心 | F8: 广东省东莞市洪梅镇望沙路115号易商物流园1楼2-6月台GUOO(备注跨境巴士注册ID) 收件人：黄朋，手机号码：13723408076
B9: 华东操作中心 义乌仓 | C9: 一件代发 | D9: 跨境巴士 | E9: A03华东操作中心 | F9: 义乌市京东亚洲一号义乌电子商务产业园1号库2楼8号门(备注跨境巴士注册ID) 收件人：小欧，手机号码：17305892219 | G9: 周一至周六 上午9:00至下午22:00
B12: WMS 系统-操作指南 | D12: 跨境巴士 系统-操作指南
B14: WMS 一件代发报价单 | D14: 跨境巴士 一件代发报价单

Sheet 备货一件代发报价
B2: 黑河国欧（GUOO)备货一件代发服务指导收费(FBP)
B3: 地址 黑龙江省黑河市爱辉区幸福乡中央东大街百合路边民互市贸易交易点 1-2号仓库 仓库联系人：杨东升 电话：19532223242 | N3: 返回目录
B4: 序号 | C4: 服务类别 | D4: 分类 | E4: 服务项 | F4: 服务内容说明 | G4: 计量单位 | H4: 服务说明 | J4: 费用 | K4: 备注 | L4: 计算公式
B5: 1 | C5: 存储服务 | D5: 通用 | E5: 存储服务 | F5: 1.商品存储保管 2.在库定期盘点 | G5: m³/天/元 | H5: 0-90天 | J5: 免费 | K5: 1、备货会按存储服务执行存货服务收费； 2、越库撤销服务、拆包服务产生的存货会执行存储服务收费； | L5: 存储费=当月每日客户在库库存体积累加*存储费标准
B6: 2 | G6: m³/天/元 | H6: 91-120天 | J6: 免费
B7: 3 | G7: m³/天/元 | H7: 121-150天 | J7: 免费
B8: 4 | G8: m³/天/元 | H8: 151-180天 | J8: 免费
B9: 5 | G9: m³/天/元 | H9: 大于180天 | J9: 4
B10: 序号 | C10: 服务类别 | D10: 分类 | E10: 服务项目 | F10: 服务内容说明 | G10: 计量单位 | H10: 件型 | K10: 备注 | L10: 计算公式
H11: 小件 | I11: 中件 | J11: 大件
H12: x≤40cm， 且y≤5KG | I12: 40cm＜x≤80cm， 或5KG＜y≤15KG | J12: 80cm＜x， 或15KG＜y
B13: 1 | C13: 库内操作服务 | D13: 备货 | E13: 入库服务 | F13: 1、到货商品清点 2、验收入库上架 | G13: 元/件 | H13: 0 | I13: 0 | J13: 0
B14: 2 | E14: 代发服务 | F14: 1、拣货下架、复核 2、打印运单 3、打包、运单粘贴 4、出库（不含耗材） | G14: 首单（元/单，含1件） | H14: 0 | I14: 0 | J14: 0
G15: 续件（元/件） | H15: 0 | I15: 0 | J15: 0

Sheet 增值服务
B2: 黑河国欧（GUOO)增值服务指导收费
B3: 地址 :黑龙江省黑河市爱辉区幸福乡中央东大街百合路边民互市贸易交易点 1-2号仓库 仓库联系人：杨东升 电话：19532223242 | M3: 返回目录
B5: 序号 | C5: 服务类别 | D5: 分类 | E5: 服务项目 | F5: 服务内容说明 | G5: 计量单位 | H5: 件型 | K5: 备注
H6: 小件 | I6: 中件 | J6: 大件
H7: x≤40cm， 且y≤5KG | I7: 40cm＜x≤80cm， 或5KG＜y≤15KG | J7: 80cm＜x， 或15KG＜y
B8: 1 | C8: 保税仓 | D8: 保税仓 | E8: 保税仓备货出口报关服务 | F8: 1、入区申报 2、出口退税申报 3、出区申报 | G8: 元/单 | H8: 500元/单，每张单限5个品名内，超过5个品名需要增加续页，续页费100元/张 | K8: 1210出口通关，整进零出集货模式
B9: 1 | C9: 增值服务 | D9: 退件 | E9: 撤销服务 | F9: 1、拦截 2、拆包 3、回库 4、上架 | G9: 元/单 | H9: 3 | I9: 4 | J9: 5
B10: 2 | E10: 销退服务 | F10: 1、退货商品清点 2、验收入库、上架 | G10: 首单（元/单，含1件） | H10: 3 | I10: 4 | J10: 5
B11: 3 | G11: 续件（元/件） | H11: 1 | I11: 1 | J11: 1.5
E12: 退仓+退货 | F12: 1、拣货下架、复核 2、打包出库、交接（不含耗材） | G12: 元/件 | H12: 1 | I12: 2 | J12: 3
F13: 3、GUOO国内免费揽收运输至黑河仓运费退件补收 | G13: 元/KG | H13: 0 | K13: 卖家自送黑河仓
G14: 元/KG | H14: 3.5 | K14: 卖家自送新厦大道180号3号仓、义乌市京东亚洲一号仓、晋江市池店镇仓
G15: 元/KG | H15: 4.5 | K15: 卖家交货至GUOO其他揽收点
B16: 4 | F16: 4、国内回程运输费用 | G16: 元/KG | H16: 回程运输方式，费用实报实销
E17: 退仓+换标+重新上架 | F17: 1、拣货下架、复核； 2、撕掉旧SKU标； 3、贴新的SKU标； 4、重新上架。 | G17: 元/件 | H17: 2 | I17: 3 | J17: 4
B18: 7 | D18: 入库增值 | E18: 代贴条码/标签 | F18: 根据客户需求,打印并代贴条码/防伪码/其他标签 | G18: 件/元 | H18: 1 | I18: 1 | J18: 1
B19: 8 | E19: 贴标签+气泡袋入库 | F19: 1、装气泡袋； 2、贴SKU标 | G19: 元/件 | H19: 2 | I19: 3 | J19: 4
B20: 9 | E20: 贴标签+气泡膜入库 | F20: 1、缠气泡膜； 2、贴SKU标 | G20: 元/件 | H20: 2 | I20: 3 | J20: 4
E21: 贴标签+快递袋入库 | F21: 1、装快递袋； 2、贴SKU标 | G21: 元/件 | H21: 2 | I21: 3 | J21: 4
E22: 贴标签+珍珠棉入库 | F22: 1、包珍珠棉； 2、贴SKU标 | G22: 元/件 | H22: 2 | I22: 3 | J22: 4
E23: 贴标签+气泡柱入库 | F23: 1、装气泡柱； 2、贴SKU标 | G23: 元/件 | H23: 3 | I23: 4 | J23: 5
E24: 缠绕膜二次包装(防水) | F24: 缠绕膜二次包装(防水) | G24: 元/件 | H24: 3 | I24: 4 | J24: 5
E25: 贴标签+气泡柱+缠绕膜 | F25: 1、装气泡柱； 2、缠绕膜； 3、贴SKU标 | G25: 元/件 | H25: 5 | I25: 8 | J25: 10
E26: 多个裸产品组合一个SKU+贴SKU+打包入库(自备包材) | F26: 1、组合2个或者2个以上SKU； 2、合并打包（自备耗材）； 3、贴SKU标 | G26: 元/件 | H26: 5 | I26: 8 | J26: 10
E27: 贴标签+纸箱入库（包括飞机盒） | F27: 1、装纸箱； 2、贴SKU标 | G27: 元/件 | H27: 单独咨询 | I27: 单独咨询 | J27: 单独咨询
E28: 加欧规头 | F28: 增加通用欧规头 | G28: 元/个 | H28: 3
E29: 增值人工工时 | F29: 其他特殊增值服务 | G29: 元/小时 | H29: 25 | K29: 需单独咨询服务需求后确认工时
B30: 10 | E30: 拍照 | F30: 按客户要求拍照 | G30: 件/元 | H30: 2
B31: 11 | E31: 拍视频 | F31: 按客户要求拍视频 | G31: 件/元 | H31: 3
B32: 12 | E32: 销毁 | F32: 销毁/弃置 | G32: 件/元 | H32: 0
B33: 13 | C33: 标准化包装服务费用 | D33: 通用 | E33: 快递袋 | F33: 快递包装 | G33: 件/元 | H33: 1 | K33: 40*50CM
B34: 14 | F34: 快递包装 | G34: 件/元 | H34: 1 | K34: 32*37CM
B35: 15 | F35: 快递包装 | G35: 件/元 | H35: 1.5 | K35: 50*60CM
B36: 16 | F36: 快递包装 | G36: 件/元 | I36: 1.5 | K36: 45*60CM
B37: 17 | F37: 快递包装 | G37: 件/元 | I37: 1.5 | K37: 60*80CM
B38: 18 | E38: 内置加厚透明气泡袋 | F38: 快递包装 | G38: 件/元 | H38: 1 | K38: 8*10cm
B39: 19 | F39: 快递包装 | G39: 件/元 | H39: 1 | K39: 30*40cm
B40: 20 | F40: 快递包装 | G40: 件/元 | H40: 1 | K40: 25*30cm
B41: 21 | F41: 快递包装 | G41: 件/元 | H41: 1 | K41: 15*20cm
B42: 22 | E42: 纸箱 | F42: 1号纸箱 | G42: 件/元 | H42: 3 | K42: 25*25*20CM
...

Sheet GUOO违禁品(品类&品名)
B2: GUOO违禁品(品类&品名)
B3: 品名
B4: 1 | C4: 蛋孵化器
B5: 2 | C5: 牙科器械
B6: 3 | C6: 制氧机
B7: 品类
B8: 1 | C8: 爆炸品：炸药、雷管、火药、子弹、烟花、鞭炮等
B9: 2 | C9: 易燃气体：打火机、打火机油、空气清新剂、摩丝(发胶、头发定型剂液化气，灭火器
B10: 3 | C10: 易燃液体：油漆、酒精、白酒、胶黏剂、粘合剂、丙酮、汽油、柴油、天那水、胶水、 粘合剂、油墨、定型水、指甲油、香水
B11: 4 | C11: 易燃固体：火柴、硫磺、明胶、硝基、磷、镁、乒乓球、蜡烛
B12: 5 | C12: 毒性物质：砷、尼古丁、氰化物、氰化钾、杀虫剂、农药
B13: 6 | C13: 腐蚀品：硫酸、盐酸、氢氧化钠、氢氧化钾、水银、双氧水、电镀用溶液、蓄电池、清洗液、清洁水
B14: 7 | C14: 弹药及其零件
B15: 8 | C15: 有毒和放射性物质
B16: 9 | C16: 生物传染性物质
B17: 10 | C17: 易腐烂的食物（例如会很快变质的食物）
B18: 11 | C18: 活的动物、鸟类、鱼类、蚕以外的生物、蜜蜂和水蛭
B19: 12 | C19: 活的植物和种子
... B43: 36 | C43: 空运产品不可以发带磁、带电（纽扣电池也不行）、液体粉末、刀具
